Workbook

Sheet STANDINGS
A1: Place | B1: Name | C1: Points | D1: Tournaments Entered | E1: Court Whist | F1: Beanbag | G1: Cribbage | H1: Volleyball | I1: Kubb | J1: Golf | K1: Backgammon | L1: Euchre | M1: Bocce | N1: Pickleball | O1: Golf Cards | P1: 3-Club Challenge | Q1: Texas Hold 'Em | R1: Total Score | S1: Average Score | T1: KEY
A2: 1 | B2: Brian Horner | C2: 95 | D2: 11 | E2: ='COURT WHIST'!D9 -> 8 | F2: =BEANBAG!D10 -> 10 | G2: 0 | H2: =VOLLEYBALL!D6 -> 10 | I2: 12 | J2: =GOLF!D3 -> 25 | K2: =BACKGAMMON!D22 -> 0 | L2: 2 | M2: 20 | N2: 25 | O2: 25 | P2: 0 | Q2: 0 | R2: =SUM(E2:Q2) -> 137 | S2: =R2/D2 -> 12.454545 | T2: Active Score
A3: 2 | B3: Kevin Horner | C3: 90 | D3: 11 | E3: ='COURT WHIST'!D33 -> 0 | F3: =BEANBAG!D3 -> 25 | G3: =CRIBBAGE!E29 -> 0 | H3: =VOLLEYBALL!D2 -> 15 | I3: 8 | J3: =GOLF!D4 -> 25 | K3: =BACKGAMMON!D10 -> 5 | L3: 0 | M3: 15 | N3: 5 | O3: 5 | P3: 25 | Q3: 0 | R3: =SUM(E3:Q3) -> 128 | S3: =R3/D3 -> 11.636364 | T3: Inactive Score
A4: 3 | B4: Adam Murphy | C4: 85 | D4: 13 | E4: ='COURT WHIST'!D14 -> 3 | F4: =BEANBAG!D22 -> 5 | G4: =CRIBBAGE!E26 -> 1 | H4: =VOLLEYBALL!D19 -> 0 | I4: 0 | J4: =GOLF!D14 -> 10 | K4: =BACKGAMMON!D3 -> 20 | L4: 25 | M4: 25 | N4: 15 | O4: 0 | P4: 1 | Q4: 10 | R4: =SUM(E4:Q4) -> 115 | S4: =R4/D4 -> 8.8461538 | T4: No Participation
A5: 4 | B5: Patty Murphy | C5: 75 | D5: 10 | E5: ='COURT WHIST'!D2 -> 25 | F5: =BEANBAG!D8 -> 10 | G5: =CRIBBAGE!E25 -> 1 | H5: 0 | I5: 0 | J5: 2 | K5: 0 | L5: 0 | M5: 15 | N5: 0 | O5: 0 | P5: 1 | Q5: 25 | R5: =SUM(E5:Q5) -> 79 | S5: =R5/D5 -> 7.9
A6: T5 | B6: Zach Leahy | C6: 70 | D6: 12 | E6: ='COURT WHIST'!D31 -> 1 | F6: =BEANBAG!D4 -> 20 | G6: =CRIBBAGE!E19 -> 2 | H6: =VOLLEYBALL!D4 -> 15 | I6: 15 | J6: =GOLF!D13 -> 15 | K6: =BACKGAMMON!D32 -> 0 | L6: 0 | M6: 5 | N6: 20 | O6: 0 | P6: 1 | Q6: 6 | R6: =SUM(E6:Q6) -> 100 | S6: =R6/D6 -> 8.3333333
A7: T5 | B7: John Murphy | C7: 70 | D7: 7 | E7: 0 | F7: =BEANBAG!D38 -> 0 | G7: =CRIBBAGE!E3 -> 20 | H7: 0 | I7: 6 | J7: =GOLF!D6 -> 20 | K7: 0 | L7: 0 | M7: 0 | N7: 0 | O7: 0 | P7: 10 | Q7: 20 | R7: =SUM(E7:Q7) -> 76 | S7: =R7/D7 -> 10.857143
A8: 7 | B8: Shane Fitzpatrick | C8: 67 | D8: 9 | E8: 0 | F8: =BEANBAG!D6 -> 15 | G8: 0 | H8: 0 | I8: 8 | J8: 0 | K8: =BACKGAMMON!D5 -> 12 | L8: 0 | M8: 25 | N8: 0 | O8: 12 | P8: 0 | Q8: 15 | R8: =SUM(E8:Q8) -> 87 | S8: =R8/D8 -> 9.6666667
A9: 8 | B9: Ben Aeshliman | C9: 65 | D9: 13 | E9: ='COURT WHIST'!D17 -> 3 | F9: =BEANBAG!D14 -> 5 | G9: =CRIBBAGE!E14 -> 3 | H9: =VOLLEYBALL!D7 -> 10 | I9: =KUBB!D3 -> 25 | J9: 2 | K9: =BACKGAMMON!D24 -> 0 | L9: 2 | M9: 10 | N9: 10 | O9: 15 | P9: 15 | Q9: 0 | R9: =SUM(E9:Q9) -> 100 | S9: =R9/D9 -> 7.6923077
A10: T9 | B10: Katie Bonicatto | C10: 62 | D10: 10 | E10: ='COURT WHIST'!D7 -> 10.5 | F10: =BEANBAG!D5 -> 20 | G10: =CRIBBAGE!E11 -> 6 | H10: =VOLLEYBALL!D5 -> 15 | I10: 12 | J10: 0 | K10: =BACKGAMMON!D9 -> 10 | L10: 2 | M10: 15 | N10: 0 | O10: 0 | P10: 0 | Q10: 0 | R10: =SUM(E10:Q10) -> 90.5 | S10: =R10/D10 -> 9.05
A11: T9 | B11: Bridget Leahy | C11: 62 | D11: 8 | E11: 0 | F11: =BEANBAG!D7 -> 15 | G11: =CRIBBAGE!E15 -> 3 | H11: 0 | I11: 12 | J11: =GOLF!D17 -> 10 | K11: 0 | L11: 10 | M11: 0 | N11: 25 | O11: 0 | P11: 0 | Q11: 0 | R11: =SUM(E11:Q11) -> 75 | S11: =R11/D11 -> 9.375
A12: 11 | B12: Luke Wieneke | C12: 60.5 | D12: 5 | E12: ='COURT WHIST'!D6 -> 10.5 | F12: =BEANBAG!D25 -> 5 | G12: =CRIBBAGE!E2 -> 25 | H12: =VOLLEYBALL!D11 -> 5 | I12: 0 | J12: =GOLF!D7 -> 20 | K12: 0 | L12: 0 | M12: 0 | N12: 0 | O12: 0 | P12: 0 | Q12: 0 | R12: =SUM(E12:Q12) -> 65.5 | S12: =R12/D12 -> 13.1
A13: 12 | B13: Ryan Fitzpatrick | C13: 58.33 | D13: 12 | E13: ='COURT WHIST'!D28 -> 1 | F13: =BEANBAG!D41 -> 0 | G13: =CRIBBAGE!E22 -> 2 | H13: =VOLLEYBALL!D21 -> 0 | I13: 20 | J13: =GOLF!D20 -> 10 | K13: 0 | L13: -1.66 | M13: 25 | N13: 5 | O13: 5 | P13: 5 | Q13: 4 | R13: =SUM(E13:Q13) -> 75.34 | S13: =R13/D13 -> 6.2783333
A14: 13 | B14: Heather Fitzpatrick | C14: 56 | D14: 6 | E14: ='COURT WHIST'!D27 -> 1 | F14: =BEANBAG!D33 -> 0 | G14: 0 | H14: 0 | I14: 0 | J14: =GOLF!D2 -> 25 | K14: =BACKGAMMON!D14 -> 5 | L14: 0 | M14: 25 | N14: 0 | O14: 0 | P14: 0 | Q14: 0 | R14: =SUM(E14:Q14) -> 56 | S14: =R14/D14 -> 9.3333333
A15: 14 | B15: Emily Horner | C15: 51 | D15: 8 | E15: ='COURT WHIST'!D29 -> 1 | F15: =BEANBAG!D2 -> 25 | G15: 0 | H15: 0 | I15: 0 | J15: 0 | K15: =BACKGAMMON!D29 -> 0 | L15: 0 | M15: 5 | N15: 0 | O15: 0 | P15: 20 | Q15: 0 | R15: =SUM(E15:Q15) -> 51 | S15: =R15/D15 -> 6.375
A16: 15 | B16: Kelly Lindseth | C16: 50 | D16: 8 | E16: ='COURT WHIST'!D23 -> 2 | F16: =BEANBAG!D48 -> 0 | G16: =CRIBBAGE!E13 -> 4 | H16: =VOLLEYBALL!D3 -> 15 | I16: 0 | J16: 0 | K16: =BACKGAMMON!D11 -> 5 | L16: 0 | M16: 20 | N16: 0 | O16: 10 | P16: 0 | Q16: 0 | R16: =SUM(E16:Q16) -> 56 | S16: =R16/D16 -> 7
A17: T16 | B17: Max Murphy | C17: 47 | D17: 7 | E17: ='COURT WHIST'!D22 -> 2 | F17: =BEANBAG!D16 -> 5 | G17: =CRIBBAGE!E20 -> 2 | H17: =VOLLEYBALL!D17 -> 2 | I17: 15 | J17: =GOLF!D5 -> 25 | K17: =BACKGAMMON!D27 -> 0 | L17: 0 | M17: 0 | N17: 0 | O17: 0 | P17: 0 | Q17: 0 | R17: =SUM(E17:Q17) -> 51 | S17: =R17/D17 -> 7.2857143
A18: T16 | B18: Teresa Aeshliman | C18: 47 | D18: 8 | E18: ='COURT WHIST'!D24 -> 2 | F18: =BEANBAG!D28 -> 0 | G18: =CRIBBAGE!E10 -> 7 | H18: 0 | I18: 0 | J18: 0 | K18: 0 | L18: 20 | M18: 5 | N18: 15 | O18: 0 | P18: 0 | Q18: 0 | R18: =SUM(E18:Q18) -> 49 | S18: =R18/D18 -> 6.125
A19: 18 | B19: Seyha Saumweber | C19: 45 | D19: 2 | E19: 0 | F19: 0 | G19: 0 | H19: 0 | I19: 0 | J19: =GOLF!D9 -> 20 | K19: =BACKGAMMON!D2 -> 25 | L19: 0 | M19: 0 | N19: 0 | O19: 0 | P19: 0 | Q19: 0 | R19: =SUM(E19:Q19) -> 45 | S19: =R19/D19 -> 22.5
A20: 19 | B20: Zack Schirmers | C20: 44.5 | D20: 6 | E20: ='COURT WHIST'!D3 -> 17.5 | F20: =BEANBAG!D18 -> 5 | G20: =CRIBBAGE!E28 -> 1 | H20: =VOLLEYBALL!D16 -> 2 | I20: 20 | J20: 0 | K20: 0 | L20: 0 | M20: 0 | N20: 0 | O20: 0 | P20: 0 | Q20: 0 | R20: =SUM(E20:Q20) -> 45.5 | S20: =R20/D20 -> 7.5833333
A21: T20 | B21: Mike Pettit | C21: 43 | D21: 5 | E21: ='COURT WHIST'!D15 -> 3 | F21: =BEANBAG!D45 -> 0 | G21: =CRIBBAGE!E7 -> 10 | H21: =VOLLEYBALL!D13 -> 5 | I21: =KUBB!D4 -> 25 | J21: 0 | K21: 0 | L21: 0 | M21: 0 | N21: 0 | O21: 0 | P21: 0 | Q21: 0 | R21: =SUM(E21:Q21) -> 43 | S21: =R21/D21 -> 8.6
A22: T20 | B22: Shawn Murphy | C22: 43 | D22: 6 | E22: ='COURT WHIST'!D16 -> 3 | F22: =BEANBAG!D30 -> 0 | G22: 0 | H22: 0 | I22: 0 | J22: =GOLF!D18 -> 10 | K22: 0 | L22: 0 | M22: 10 | N22: 20 | O22: 0 | P22: 0 | Q22: 0 | R22: =SUM(E22:Q22) -> 43 | S22: =R22/D22 -> 7.1666667
A23: 22 | B23: Robbie Murphy | C23: 41 | D23: 4 | E23: 0 | F23: 0 | G23: 0 | H23: 0 | I23: 0 | J23: =GOLF!D10 -> 15 | K23: 0 | L23: 1 | M23: 0 | N23: 5 | O23: 0 | P23: 20 | Q23: 0 | R23: =SUM(E23:Q23) -> 41 | S23: =R23/D23 -> 10.25
A24: T23 | B24: John Horner | C24: 38 | D24: 8 | E24: ='COURT WHIST'!D35 -> 0 | F24: =BEANBAG!D40 -> 0 | G24: =CRIBBAGE!E18 -> 3 | H24: =VOLLEYBALL!D8 -> 10 | I24: 20 | J24: 0 | K24: 0 | L24: 0 | M24: 5 | N24: 0 | O24: 0 | P24: 0 | Q24: 0 | R24: =SUM(E24:Q24) -> 38 | S24: =R24/D24 -> 4.75
A25: T23 | B25: Colleen Irwin | C25: 38 | D25: 8 | E25: ='COURT WHIST'!D18 -> 3 | F25: =BEANBAG!D27 -> 0 | G25: 0 | H25: 0 | I25: 0 | J25: 0 | K25: =BACKGAMMON!D17 -> 5 | L25: 8 | M25: 20 | N25: 5 | O25: 0 | P25: 0 | Q25: 0 | R25: =SUM(E25:Q25) -> 41 | S25: =R25/D25 -> 5.125
A26: 25 | B26: Michelle Pettit | C26: 37 | D26: 6 | E26: ='COURT WHIST'!D34 -> 0 | F26: =BEANBAG!D12 -> 10 | G26: =CRIBBAGE!E4 -> 15 | H26: =VOLLEYBALL!D9 -> 10 | I26: 0 | J26: 2 | K26: 0 | L26: 0 | M26: 0 | N26: 0 | O26: 0 | P26: 0 | Q26: 0 | R26: =SUM(E26:Q26) -> 37 | S26: =R26/D26 -> 6.1666667
A27: T26 | B27: Timmy Leahy | C27: 36 | D27: 6 | E27: ='COURT WHIST'!D5 -> 12 | F27: =BEANBAG!D49 -> 0 | G27: =CRIBBAGE!E17 -> 3 | H27: 0 | I27: 0 | J27: 0 | K27: =BACKGAMMON!D6 -> 11 | L27: 0 | M27: 10 | N27: 0 | O27: 0 | P27: 0 | Q27: 0 | R27: =SUM(E27:Q27) -> 36 | S27: =R27/D27 -> 6
A28: T26 | B28: Anna Horner | C28: 36 | D28: 8 | E28: 0 | F28: =BEANBAG!D20 -> 5 | G28: =CRIBBAGE!E9 -> 8 | H28: =VOLLEYBALL!D18 -> 0 | I28: 0 | J28: 0 | K28: =BACKGAMMON!D20 -> 0 | L28: 0 | M28: 20 | N28: 0 | O28: 3 | P28: 0 | Q28: 0 | R28: =SUM(E28:Q28) -> 36 | S28: =R28/D28 -> 4.5
A29: 28 | B29: Brendan Lindseth | C29: 34 | D29: 7 | E29: 0 | F29: 0 | G29: 0 | H29: 0 | I29: 0 | J29: =GOLF!D11 -> 15 | K29: =BACKGAMMON!D23 -> 0 | L29: 0 | M29: 0 | N29: 10 | O29: 3 | P29: 5 | Q29: 4 | R29: =SUM(E29:Q29) -> 37 | S29: =R29/D29 -> 5.2857143
A30: 29 | B30: Cindy Irwin | C30: 32 | D30: 11 | E30: ='COURT WHIST'!D25 -> 2 | F30: =BEANBAG!D9 -> 10 | G30: =CRIBBAGE!E24 -> 1 | H30: 0 | I30: 0 | J30: 2 | K30: =BACKGAMMON!D28 -> 0 | L30: 1 | M30: 0 | N30: 0 | O30: 5 | P30: 10 | Q30: 7 | R30: =SUM(E30:Q30) -> 38 | S30: =R30/D30 -> 3.4545455
A31: 30 | B31: Tricia Stahlmann | C31: 30.33 | D31: 9 | E31: ='COURT WHIST'!D8 -> 9 | F31: =BEANBAG!D34 -> 0 | G31: =CRIBBAGE!E16 -> 3 | H31: 0 | I31: 0 | J31: 0 | K31: =BACKGAMMON!D26 -> 0 | L31: -1.66 | M31: 0 | N31: 0 | O31: 20 | P31: 0 | Q31: 0 | R31: =SUM(E31:Q31) -> 30.34 | S31: =R31/D31 -> 3.3711111
A32: 31 | B32: Kyle Willette | C32: 28.5 | D32: 7 | E32: ='COURT WHIST'!D13 -> 4.5 | F32: =BEANBAG!D46 -> 0 | G32: =CRIBBAGE!E5 -> 12 | H32: =VOLLEYBALL!D20 -> 0 | I32: 0 | J32: 2 | K32: =BACKGAMMON!D8 -> 10 | L32: 0 | M32: 0 | N32: 0 | O32: 0 | P32: 0 | Q32: 0 | R32: =SUM(E32:Q32) -> 28.5 | S32: =R32/D32 -> 4.0714286
A33: T32 | B33: Samantha Pettit | C33: 25 | D33: 2 | E33: 0 | F33: 0 | G33: 0 | H33: 0 | I33: =KUBB!D2 -> 25 | J33: 0 | K33: 0 | L33: 0 | M33: 0 | N33: 0 | O33: 0 | P33: 0 | Q33: 0 | R33: =SUM(E33:Q33) -> 25 | S33: =R33/D33 -> 12.5
A34: T32 | B34: Will Modrow | C34: 25 | D34: 8 | E34: 0 | F34: =BEANBAG!D15 -> 5 | G34: 0 | H34: 0 | I34: 15 | J34: 0 | K34: =BACKGAMMON!D33 -> 0 | L34: 0 | M34: 5 | N34: 0 | O34: 0 | P34: 0 | Q34: 0 | R34: =SUM(E34:Q34) -> 25 | S34: =R34/D34 -> 3.125
A35: T32 | B35: Lauren Horner | C35: 25 | D35: 2 | E35: 0 | F35: 0 | G35: 0 | H35: 0 | I35: 0 | J35: 0 | K35: 0 | L35: 0 | M35: 0 | N35: 0 | O35: 0 | P35: 25 | Q35: 0 | R35: =SUM(E35:Q35) -> 25 | S35: =R35/D35 -> 12.5
A36: 35 | B36: Mackenzie Leahy | C36: 24.84 | D36: 11 | E36: ='COURT WHIST'!D37 -> -2.5 | F36: =BEANBAG!D21 -> 5 | G36: =CRIBBAGE!E33 -> -5 | H36: =VOLLEYBALL!D14 -> 2 | I36: 0 | J36: 0 | K36: =BACKGAMMON!D13 -> 5 | L36: -1.66 | M36: 10 | N36: 5 | O36: 0 | P36: 0 | Q36: 12 | R36: =SUM(E36:Q36) -> 29.84 | S36: =R36/D36 -> 2.7127273
A37: T36 | B37: Tim Pettit | C37: =SUM(E37:H37) -> 23.5 | D37: 5 | E37: ='COURT WHIST'!D12 -> 4.5 | F37: =BEANBAG!D11 -> 10 | G37: =CRIBBAGE!E8 -> 9 | H37: 0 | I37: 0 | J37: 0 | K37: =BACKGAMMON!D31 -> 0 | L37: 0 | M37: 0 | N37: 0 | O37: 0 | P37: 0 | Q37: 0 | R37: =SUM(E37:Q37) -> 23.5 | S37: =R37/D37 -> 4.7
A38: T36 | B38: Angie Willette | C38: =SUM(E38:H38) -> 23.5 | D38: 6 | E38: ='COURT WHIST'!D4 -> 17.5 | F38: =BEANBAG!D42 -> 0 | G38: =CRIBBAGE!E27 -> 1 | H38: =VOLLEYBALL!D10 -> 5 | I38: 0 | J38: 0 | K38: =BACKGAMMON!D18 -> 0 | L38: 0 | M38: 0 | N38: 0 | O38: 0 | P38: 0 | Q38: 0 | R38: =SUM(E38:Q38) -> 23.5 | S38: =R38/D38 -> 3.9166667
A39: 38 | B39: Shaun Irwin | C39: 22 | D39: 8 | E39: ='COURT WHIST'!D21 -> 2 | F39: =BEANBAG!D32 -> 0 | G39: 0 | H39: 0 | I39: 0 | J39: =GOLF!D16 -> 10 | K39: =BACKGAMMON!D15 -> 5 | L39: 2 | M39: 0 | N39: 5 | O39: 0 | P39: 0 | Q39: 0 | R39: =SUM(E39:Q39) -> 24 | S39: =R39/D39 -> 3
A40: 39 | B40: Celina Aeshliman | C40: 21.5 | D40: 7 | E40: ='COURT WHIST'!D11 -> 6.5 | F40: =BEANBAG!D23 -> 5 | G40: 0 | H40: 0 | I40: 0 | J40: 0 | K40: =BACKGAMMON!D25 -> 0 | L40: 0 | M40: 5 | N40: 5 | O40: 0 | P40: 0 | Q40: 0 | R40: =SUM(E40:Q40) -> 21.5 | S40: =R40/D40 -> 3.0714286
...

Sheet COURT WHIST
A1: Place | B1: Name | C1: Points | D1: PC Points | F1: 2023 | G1: Place | H1: Points | I1: PC Points
A2: 1 | B2: Patty Murphy | C2: 170 | D2: 25 | F2: Shawn Murphy | G2: 1 | H2: 177 | I2: 25
A3: T2 | B3: Zack Schirmers | C3: 167 | D3: 17.5 | F3: Larry Aeshliman | G3: 2 | H3: 173 | I3: 20
A4: T2 | B4: Angie Willette | C4: 167 | D4: 17.5 | F4: Cindy Irwin | G4: 3 | H4: 171 | I4: 15
A5: 4 | B5: Timmy Leahy | C5: 164.5 | D5: 12 | F5: Rick Pettit | G5: 4 | H5: 167 | I5: 12
A6: T5 | B6: Luke Wieneke | C6: 162 | D6: 10.5 | F6: Ailish Fitzpatrick | G6: 5 | H6: 164 | I6: 11
A7: T5 | B7: Katie Bonicatto | C7: 162 | D7: 10.5 | F7: Tim Pettit | G7: T6 | H7: 161 | I7: 9.5
A8: 7 | B8: Tricia Stahlmann | C8: 161 | D8: 9 | F8: Angi Willette | G8: T6 | H8: 161 | I8: 9.5
A9: 8 | B9: Brian Horner | C9: 160 | D9: 8 | F9: Teresa Aeshliman | G9: 8 | H9: 160 | I9: 8
A10: T9 | B10: (Cincy) Rob Murphy | C10: 159 | D10: 6.5 | F10: Bridget Leahy | G10: T9 | H10: 159 | I10: 6.5
A11: T9 | B11: Celina Aeshliman | C11: 159 | D11: 6.5 | F11: Tricia Stahlman | G11: T9 | H11: 159 | I11: 6.5
A12: T11 | B12: Tim Pettit | C12: 158 | D12: 4.5 | F12: Adam Murphy | G12: 11 | H12: 158 | I12: 5
A13: T11 | B13: Kyle Willette | C13: 158 | D13: 4.5 | F13: Uncle Rob Murphy | G13: T12 | H13: 157 | I13: 3.5
A14: T13 | B14: Adam Murphy | C14: 157 | D14: 3 | F14: Matt Stahlman | G14: T12 | H14: 157 | I14: 3.5
A15: T13 | B15: Mike Pettit | C15: 157 | D15: 3 | F15: Patty Murphy | G15: 14 | H15: 156 | I15: 3
A16: 15 | B16: Shawn Murphy | C16: 156 | D16: 3 | F16: Samantha Pettit | G16: 15 | H16: 155 | I16: 3
A17: T16 | B17: Ben Aeshliman | C17: 154 | D17: 3 | F17: Peggy Bonicatto | G17: T16 | H17: 154 | I17: 3
A18: T16 | B18: Colleen Irwin | C18: 154 | D18: 3 | F18: Zach Leahy | G18: T16 | H18: 154 | I18: 3
A19: 18 | B19: Matt Stahlmann | C19: 153 | D19: 3 | F19: Luke Wieneke | G19: 18 | H19: 153 | I19: 3
A20: 19 | B20: Peggy Bonicatto | C20: 152 | D20: 2 | F20: Ryan Fitzpatrick | G20: 19 | H20: 152 | I20: 2
A21: 20 | B21: Shaun Irwin | C21: 150 | D21: 2 | F21: Timmy Leahy | G21: 20 | H21: 150 | I21: 2
A22: 21 | B22: Max Murphy | C22: 149 | D22: 2 | F22: Kyle Willette | G22: T21 | H22: 149 | I22: 2
A23: 22 | B23: Kelly Lindseth | C23: 147 | D23: 2 | F23: Colleen Saumweber | G23: T21 | H23: 149 | I23: 2
A24: 23 | B24: Teresa Aeshliman | C24: 146 | D24: 2 | F24: Shane Fitzpatrick | G24: T23 | H24: 148 | I24: 2
A25: 24 | B25: Cindy Irwin | C25: 144.5 | D25: 2 | F25: Max Murphy | G25: T23 | H25: 148 | I25: 2
A26: 25 | B26: Donna Weineke | C26: 142 | D26: 1 | F26: Zack Schirmers | G26: 25 | H26: 147 | I26: 1
A27: 26 | B27: Heather Fitzpatrick | C27: 141 | D27: 1 | F27: Donna Bonicatto | G27: 26 | H27: 146 | I27: 1
A28: 27 | B28: Ryan Fitzpatrick | C28: 140.5 | D28: 1 | F28: Barry Fitzpatrick | G28: 27 | H28: 144 | I28: 1
A29: 28 | B29: Emily Horner | C29: 139 | D29: 1 | F29: Shaun Irwin | G29: 28 | H29: 143 | I29: 1
A30: 29 | B30: Rick Pettit | C30: 138.5 | D30: 1 | F30: Ben Aeshliman | G30: 29 | H30: 141 | I30: 1
A31: 30 | B31: Zach Leahy | C31: 137 | D31: 1 | F31: John Murphy | G31: T30 | H31: 137 | I31: 1
A32: T31 | B32: Colleen Saumweber | C32: 136 | D32: 0 | F32: Katie Bonicatto | G32: T30 | H32: 137 | I32: 1
A33: T31 | B33: Kevin Horner | C33: 136 | D33: 0 | F33: Emily Horner | G33: T32 | H33: 136 | I33: 0
A34: 33 | B34: Michelle Pettit | C34: 135 | D34: 0 | F34: Tim Leahy | G34: T32 | H34: 136 | I34: 0
A35: 34 | B35: John Horner | C35: 132 | D35: 0 | F35: Michelle Pettit | G35: T32 | H35: 136 | I35: 0
A36: T35 | B36: Alice Pettit | C36: 128 | D36: -2.5 | F36: Brian Horner | G36: 35 | H36: 134 | I36: 0
A37: T35 | B37: Mackenzie Leahy | C37: 128 | D37: -2.5 | F37: Mackenzie Leahy | G37: 36 | H37: 121 | I37: -5

Sheet BEANBAG
A1: Place | B1: Name | C1: Games Won | D1: PC Points
A2: 1 | B2: Emily Horner | C2: 5 | D2: 25
A3: 1 | B3: Kevin Horner | C3: 5 | D3: 25
A4: 2 | B4: Zach Leahy | C4: 4 | D4: 20
A5: 2 | B5: Katie Bonicatto | C5: 4 | D5: 20
A6: 3 | B6: Shane Fitzpatrick | C6: 3 | D6: 15
A7: 3 | B7: Bridget Leahy | C7: 3 | D7: 15
A8: T4 | B8: Patty Murphy | C8: 2 | D8: 10
A9: T4 | B9: Cindy Irwin | C9: 2 | D9: 10
A10: T4 | B10: Brian Horner | C10: 2 | D10: 10
A11: T4 | B11: Tim Pettit | C11: 2 | D11: 10
A12: T4 | B12: Michelle Pettit | C12: 2 | D12: 10
A13: T4 | B13: Andrew Breviu | C13: 2 | D13: 10
A14: T7 | B14: Ben Aeshliman | C14: 1 | D14: 5
A15: T7 | B15: Will Modrow | C15: 1 | D15: 5
A16: T7 | B16: Max Murphy | C16: 1 | D16: 5
A17: T7 | B17: Matt Stahlmann | C17: 1 | D17: 5
A18: T7 | B18: Zack Schirmers | C18: 1 | D18: 5
A19: T7 | B19: Sawyer Scherer | C19: 1 | D19: 5
... A49: T13 | B49: Timmy Leahy | C49: 0 | D49: 0

Sheet CRIBBAGE
A1: Place | B1: Name | C1: Wins | D1: Points | E1: PC Points
A2: 1 | B2: Luke Wieneke | C2: 5 | D2: 73 | E2: 25
A3: 2 | B3: John Murphy | C3: 4 | D3: 109 | E3: 20
A4: 3 | B4: Michelle Pettit | C4: 4 | D4: 100 | E4: 15
A5: 4 | B5: Kyle Willette | C5: 4 | D5: 65 | E5: 12
A6: 5 | B6: Larry Aeshliman | C6: 4 | D6: 49 | E6: 11
A7: 6 | B7: Mike Pettit | C7: 3 | D7: 94 | E7: 10
A8: 7 | B8: Tim Pettit | C8: 3 | D8: 79 | E8: 9
A9: 8 | B9: Anna Horner | C9: 3 | D9: 74 | E9: 8
A10: 9 | B10: Teresa Aeshliman | C10: 3 | D10: 70 | E10: 7
A11: 10 | B11: Katie Bonicatto | C11: 3 | D11: 60 | E11: 6
A12: 11 | B12: Peggy Bonicatto | C12: 3 | D12: 54 | E12: 5
A13: 12 | B13: Kelly Lindseth | C13: 3 | D13: 45 | E13: 4
... A25: 24 | B25: Patty Murphy | C25: 2 | D25: 22 | E25: 1
A26: T25 | B26: Adam Murphy | C26: 2 | D26: 20 | E26: 1
A27: T25 | B27: Angie Willette | C27: 2 | D27: 20 | E27: 1
A28: 27 | B28: Zack Schirmers | C28: 1 | D28: 37 | E28: 1
A29: 28 | B29: Kevin Horner | C29: 1 | D29: 27 | E29: 0
A30: 29 | B30: Andrew Breviu | C30: 1 | D30: 24 | E30: 0
A31: 30 | B31: Alice Pettit | C31: 1 | D31: 21 | E31: 0
A32: 31 | B32: Rick Pettit | C32: 1 | D32: 3 | E32: 0
A33: 32 | B33: Mackenzie Leahy | C33: 0 | D33: 0 | E33: -5

Sheet VOLLEYBALL
A1: Place | B1: Name | C1: Games Won | D1: PC Points
A2: 1 | B2: Kevin Horner | C2: 5 | D2: 15
A3: 1 | B3: Kelly Lindseth | C3: 5 | D3: 15
A4: 1 | B4: Zach Leahy | C4: 5 | D4: 15
A5: 1 | B5: Katie Bonicatto | C5: 5 | D5: 15
A6: 2 | B6: Brian Horner | C6: 4 | D6: 10
A7: 2 | B7: Ben Aeshliman | C7: 4 | D7: 10
A8: 2 | B8: John Horner | C8: 4 | D8: 10
A9: 2 | B9: Michelle Pettit | C9: 4 | D9: 10
A10: 3 | B10: Angie Willette | C10: 3 | D10: 5
A11: 3 | B11: Luke Wieneke | C11: 3 | D11: 5
A12: 3 | B12: Andrew Breviu | C12: 3 | D12: 5
A13: 3 | B13: Mike Pettit | C13: 3 | D13: 5
... A21: 5 | B21: Ryan Fitzpatrick | C21: 0 | D21: 0

Sheet KUBB
A1: Place | B1: Name | C1: Games Won | D1: PC Points
A2: 1 | B2: Samantha Pettit | C2: 4 | D2: 25
A3: 1 | B3: Ben Aeshliman | C3: 4 | D3: 25
A4: 1 | B4: Mike Pettit | C4: 4 | D4: 25
A5: 2 | B5: John Horner | C5: 3 | D5: 20
A6: 2 | B6: Ryan Fitzpatrick | C6: 3 | D6: 20
A7: 2 | B7: Zack Schirmers | C7: 3 | D7: 20
A8: 3 | B8: Max Murphy | C8: 2 | D8: 15
A9: 3 | B9: Will Modrow | C9: 2 | D9: 15
A10: 3 | B10: Zach Leahy | C10: 2 | D10: 15
A11: 4 | B11: Dave Modrow | C11: 3 | D11: 12
A12: 4 | B12: Katie Bonicatto | C12: 3 | D12: 12
A13: 4 | B13: Brian Horner | C13: 3 | D13: 12
... A19: 6 | B19: Sawyer Scherer | C19: 2 | D19: 6
A20: T7 | B20: Colleen Irwin | C20: 0 | D20: 0
A21: T7 | B21: Angie Willette | C21: 0 | D21: 0
A22: T7 | B22: Molly Murphy | C22: 0 | D22: 0
A23: T7 | B23: Anna Horner | C23: 0 | D23: 0
A24: T7 | B24: Patty Murphy | C24: 0 | D24: 0
A25: T7 | B25: Matt Stahlmann | C25: 0 | D25: 0
A26: T7 | B26: Tricia Stahlmann | C26: 0 | D26: 0
A27: T7 | B27: Michelle Pettit | C27: 0 | D27: 0
A28: T7 | B28: Tim Pettit | C28: 0 | D28: 0
A29: T7 | B29: Kyle Willette | C29: 0 | D29: 0
A30: T7 | B30: Timmy Leahy | C30: 0 | D30: 0
A31: T7 | B31: Beth Horner | C31: 0 | D31: 0
... A40: T7 | B40: Kelly Lindseth | C40: 0 | D40: 0

Sheet GOLF
A1: Place | B1: Name | C1: Score | D1: PC Points
A2: 1 | B2: Heather Fitzpatrick | C2: 33 | D2: 25
A3: 1 | B3: Brian Horner | C3: 33 | D3: 25
A4: 1 | B4: Kevin Horner | C4: 33 | D4: 25
A5: 1 | B5: Max Murphy | C5: 33 | D5: 25
A6: 2 | B6: John Murphy | C6: 34 | D6: 20
A7: 2 | B7: Luke Wieneke | C7: 34 | D7: 20
A8: 2 | B8: Molly Murphy | C8: 34 | D8: 20
A9: 2 | B9: Seyha Saumweber | C9: 34 | D9: 20
A10: 3 | B10: Robbie Murphy | C10: 34 | D10: 15
A11: 3 | B11: Brendan Lindseth | C11: 34 | D11: 15
A12: 3 | B12: Donna Wieneke | C12: 34 | D12: 15
A13: 3 | B13: Zach Leahy | C13: 34 | D13: 15
A14: T4 | B14: Adam Murphy | C14: 35 | D14: 10
A15: T4 | B15: Bob Bonicatto | C15: 35 | D15: 10
A16: T4 | B16: Shaun Irwin | C16: 35 | D16: 10
A17: T4 | B17: Bridget Leahy | C17: 35 | D17: 10
A18: T4 | B18: Shawn Murphy | C18: 35 | D18: 10
A19: T4 | B19: Cathy Murphy | C19: 35 | D19: 10
A20: T4 | B20: Ryan Fitzpatrick | C20: 35 | D20: 10
A21: T4 | B21: Zach Schmoll | C21: 35 | D21: 10
A22: T6 | B22: (Cincy) Rob Murphy | C22: 36 | D22: 2
A23: T6 | B23: Ben Aeshliman | C23: 36 | D23: 2
A24: T6 | B24: Patty Murphy | C24: 36 | D24: 2
A25: T6 | B25: Michelle Pettit | C25: 36 | D25: 2
... A29: T6 | B29: Kyle Willette | C29: 36 | D29: 2
A30: 8 | B30: Barry Fitzpatrick | C30: 38 | D30: 0
A31: 8 | B31: Zack Schirmers | C31: 38 | D31: 0
A32: 8 | B32: Lauren Horner | C32: 38 | D32: 0
A33: 8 | B33: Shane Fitzpatrick | C33: 38 | D33: 0

Sheet BACKGAMMON
A1: Place | B1: Name | C1: Games Won | D1: PC Points
A2: 1 | B2: Seyha Saumweber | C2: 5 | D2: 25
A3: 2 | B3: Adam Murphy | C3: 4 | D3: 20
A4: 3 | B4: Lauren Lindseth | C4: 4 | D4: 15
A5: 4 | B5: Shane Fitzpatrick | C5: 3 | D5: 12
A6: T5 | B6: Timmy Leahy | C6: 2 | D6: 11
A7: T5 | B7: Jason Lindseth | C7: 2 | D7: 10
A8: T5 | B8: Kyle Willette | C8: 2 | D8: 10
A9: T5 | B9: Katie Bonicatto | C9: 2 | D9: 10
A10: T9 | B10: Kevin Horner | C10: 1 | D10: 5
A11: T9 | B11: Kelly Lindseth | C11: 1 | D11: 5
A12: T9 | B12: Colleen Saumweber | C12: 1 | D12: 5
A13: T9 | B13: Mackenzie Leahy | C13: 1 | D13: 5
A14: T9 | B14: Heather Fitzpatrick | C14: 1 | D14: 5
A15: T9 | B15: Shaun Irwin | C15: 1 | D15: 5
A16: T9 | B16: Peggy Bonicatto | C16: 1 | D16: 5
A17: T9 | B17: Colleen Irwin | C17: 1 | D17: 5
... A34: T17 | B34: Alice Pettit | C34: 0 | D34: 0

Sheet EUCHRE
A1: Place | B1: Name | C1: PC Points
A2: 1 | B2: Adam Murphy | C2: 25
A3: 2 | B3: Teresa Aeshliman | C3: 20
A4: 3 | B4: Daniel Horner | C4: 15
A5: 4 | B5: Terri Theis | C5: 12
A6: 5 | B6: Bridget Leahy | C6: 10
A7: 6 | B7: Colleen Irwin | C7: 8
A8: 7 | B8: Larry Aeshliman | C8: 6
A9: 8 | B9: Colleen Saumweber | C9: 4
A10: 9 | B10: Brian Horner | C10: 2
A11: 10 | B11: Ben Aeshliman | C11: 2
A12: 11 | B12: Shaun Irwin | C12: 2
A13: 12 | B13: Katie Bonicatto | C13: 2
... A17: 16 | B17: Peggy Bonicatto | C17: 0
A18: T15 | B18: Patty Murphy | C18: 0
A19: 18 | B19: Mackenzie Leahy | C19: -1.66
A20: 19 | B20: Tricia Stahlmann | C20: -1.66
A21: 20 | B21: Ryan Fitzpatrick | C21: -1.66

Sheet BOCCE
A1: Place | B1: Name | C1: Games Won | D1: PC Points
A2: 1 | B2: Adam Murphy | C2: 3 | D2: 25
A3: 1 | B3: Ryan Fitzpatrick | C3: 3 | D3: 25
A4: 1 | B4: Heather Fitzpatrick | C4: 3 | D4: 25
A5: 1 | B5: Shane Fitzpatrick | C5: 3 | D5: 25
A6: 2 | B6: Anna Horner | C6: 2 | D6: 20
A7: 2 | B7: Kelly Lindseth | C7: 2 | D7: 20
A8: 2 | B8: Brian Horner | C8: 2 | D8: 20
A9: 2 | B9: Colleen Irwin | C9: 2 | D9: 20
A10: 3 | B10: Kevin Horner | C10: 2 | D10: 15
A11: 3 | B11: Patty Murphy | C11: 2 | D11: 15
A12: 3 | B12: Katie Bonicatto | C12: 2 | D12: 15
A13: 3 | B13: Nora Modrow | C13: 2 | D13: 15
... A17: 4 | B17: Mackenzie Leahy | C17: 1 | D17: 10
A18: T5 | B18: John Horner | C18: 1 | D18: 5
A19: T5 | B19: Celina Aeshliman | C19: 1 | D19: 5
A20: T5 | B20: Zach Robertson | C20: 1 | D20: 5
A21: T5 | B21: Teresa Aeshliman | C21: 1 | D21: 5
A22: T5 | B22: Zach Leahy | C22: 1 | D22: 5
A23: T5 | B23: Dave (Sr.) Modrow | C23: 1 | D23: 5
A24: T5 | B24: Will Modrow | C24: 1 | D24: 5
A25: T5 | B25: Emily Horner | C25: 1 | D25: 5
A26: T7 | B26: John Murphy | C26: 0 | D26: 0
A27: T7 | B27: Peggy Bonicatto | C27: 0 | D27: 0
A28: T7 | B28: Beth Horner | C28: 0 | D28: 0
A29: T7 | B29: Brendan Lindseth | C29: 0 | D29: 0
... A33: T7 | B33: Colleen Modrow | C33: 0 | D33: 0

Sheet PICKLEBALL
A1: Place | B1: Name | C1: Games Won | D1: PC Points
A2: 1 | B2: Brian Horner | C2: 3 | D2: 25
A3: 1 | B3: Bridget Leahy | C3: 3 | D3: 25
A4: 2 | B4: Shawn Murphy | C4: 2 | D4: 20
A5: 2 | B5: Zach Leahy | C5: 2 | D5: 20
A6: 3 | B6: Adam Murphy | C6: 2 | D6: 15
A7: 3 | B7: Teresa Aeshliman | C7: 2 | D7: 15
A8: 4 | B8: Ben Aeshliman | C8: 1 | D8: 10
A9: 4 | B9: Brendan Lindseth | C9: 1 | D9: 10
A10: T5 | B10: Kevin Horner | C10: 0 | D10: 5
A11: T5 | B11: Colleen Irwin | C11: 0 | D11: 5
A12: T5 | B12: Beth Horner | C12: 0 | D12: 5
A13: T5 | B13: Ryan Fitzpatrick | C13: 0 | D13: 5
A14: T5 | B14: Mackenzie Leahy | C14: 0 | D14: 5
A15: T5 | B15: Celina Aeshliman | C15: 0 | D15: 5
A16: T5 | B16: Shaun Irwin | C16: 0 | D16: 5
A17: T5 | B17: Robbie Murphy | C17: 0 | D17: 5
A18: T17 | B18: Anna Horner | C18: 0 | D18: 0
A19: T17 | B19: John Horner | C19: 0 | D19: 0
A20: T17 | B20: Emily Horner | C20: 0 | D20: 0
A21: T17 | B21: Shane Fitzpatrick | C21: 0 | D21: 0
... A26: T17 | B26: Katie Bonicatto | C26: 0 | D26: 0

Sheet GOLF CARDS
A1: Place | B1: Name | C1: PC Points
A2: 1 | B2: Brian Horner | C2: 25
A3: 2 | B3: Tricia Stahlmann | C3: 20
A4: 3 | B4: Ben Aeshliman | C4: 15
A5: 4 | B5: Shane Fitzpatrick | C5: 12
A6: 5 | B6: Kelly Lindseth | C6: 10
A7: T6 | B7: Kevin Horner | C7: 5
A8: T6 | B8: Ailish Fitzpatrick | C8: 5
A9: T6 | B9: Cindy Irwin | C9: 5
A10: T6 | B10: Ryan Fitzpatrick | C10: 5
A11: T6 | B11: Nora Modrow | C11: 5
A12: T11 | B12: Anna Horner | C12: 3
A13: T11 | B13: Brendan Lindseth | C13: 3
A14: T11 | B14: Kathleen Murphy | C14: 3
A15: T11 | B15: David Modrow | C15: 3
A16: T11 | B16: Peggy Bonicatto | C16: 3
A17: T16 | B17: Adam Murphy | C17: 0
A18: T16 | B18: Katie Bonicatto | C18: 0
... A31: T16 | B31: John Murphy | C31: 0

Sheet 3-CLUB CHALLENGE
A1: Place | B1: Name | C1: Score | D1: PC Points
A2: 1 | B2: Lauren Horner | C2: 38 | D2: 25
A3: 1 | B3: Kevin Horner | C3: 38 | D3: 25
A4: 2 | B4: Emily Horner | C4: 38 | D4: 20
A5: 2 | B5: Robbie Murphy | C5: 38 | D5: 20
A6: 3 | B6: Ben Aeshliman | C6: 38 | D6: 15
A7: 3 | B7: Barry Fitzpatrick | C7: 38 | D7: 15
A8: 4 | B8: John Murphy | C8: 39 | D8: 10
A9: 4 | B9: Cindy Irwin | C9: 39 | D9: 10
A10: 5 | B10: Brendan Lindseth | C10: 40 | D10: 5
A11: 5 | B11: Ryan Fitzpatrick | C11: 40 | D11: 5
A12: T6 | B12: Daniel Horner | C12: 41 | D12: 1
A13: T6 | B13: Zach Leahy | C13: 41 | D13: 1
A14: T6 | B14: Adam Murphy | C14: 41 | D14: 1
A15: T6 | B15: Patty Murphy | C15: 41 | D15: 1
A16: 8 | B16: Brian Horner | C16: 43 | D16: 0
A17: 8 | B17: Will Modrow | C17: 43 | D17: 0
A18: 8 | B18: Shane Fitzpatrick | C18: 43 | D18: 0

Sheet TEXAS HOLD EM
A1: Place | B1: Name | C1: PC Points
A2: 1 | B2: Patty Murphy | C2: 25
A3: 2 | B3: John Murphy | C3: 20
A4: 3 | B4: Shane Fitzpatrick | C4: 15
A5: 4 | B5: Mackenzie Leahy | C5: 12
A6: 5 | B6: Adam Murphy | C6: 10
A7: 6 | B7: Rick Pettit | C7: 9
A8: 7 | B8: Peggy Bonicatto | C8: 8
A9: 8 | B9: Cindy Irwin | C9: 7
A10: 9 | B10: Zach Leahy | C10: 6
A11: T10 | B11: Ryan Fitzpatrick | C11: 4
A12: T10 | B12: John Dixon | C12: 4
A13: T10 | B13: Brendan Lindseth | C13: 4
A14: T13 | B14: Tricia Stahlmann | C14: 0
A15: T13 | B15: Terri Theis | C15: 0
A16: T13 | B16: Bridget Leahy | C16: 0
A17: T13 | B17: Ben Aeshliman | C17: 0
A18: T13 | B18: Celina Aeshliman | C18: 0
A19: T13 | B19: Teresa Aeshliman | C19: 0
A20: T13 | B20: Will Modrow | C20: 0
A21: T13 | B21: Barry Fitzpatrick | C21: 0
